[2024-10-24T21:20:09.009+0000] {task_context_logger.py:104} ERROR - Executor reports task instance <TaskInstance: DAG_PYTHON_OPERATOR.task_python manual__2024-10-24T21:12:13.006531+00:00 [queued]> finished (failed) although the task says it's queued. (Info: None) Was the task killed externally?
